2022-10-11 17:11:02,724 -  nornir.core -     INFO -        run() - Running task 'randomtest' with args {} on 4 hosts
2022-10-11 18:05:31,539 -  nornir.core -     INFO -        run() - Running task 'randomtest' with args {} on 4 hosts
2022-10-11 18:06:28,374 -  nornir.core -     INFO -        run() - Running task 'randomtest' with args {} on 4 hosts
2022-10-11 18:10:07,903 -  nornir.core -     INFO -        run() - Running task 'test_show_command' with args {} on 4 hosts
2022-10-11 18:10:07,906 - nornir.core.task -    ERROR -      start() - Host 'R1': task 'send_command' failed with traceback:
Traceback (most recent call last):
  File "/home/lj/NetDevOps/Templating/.venv/lib/python3.10/site-packages/scrapli/factory.py", line 157, in _get_community_platform_details
    scrapli_community_platform = importlib.import_module(
  File "/usr/lib/python3.10/importlib/__init__.py", line 126, in import_module
    return _bootstrap._gcd_import(name[level:], package, level)
  File "<frozen importlib._bootstrap>", line 1050, in _gcd_import
  File "<frozen importlib._bootstrap>", line 1027, in _find_and_load
  File "<frozen importlib._bootstrap>", line 1004, in _find_and_load_unlocked
ModuleNotFoundError: No module named 'scrapli_community.iOS'

The above exception was the direct cause of the following exception:

Traceback (most recent call last):
  File "/home/lj/NetDevOps/Templating/.venv/lib/python3.10/site-packages/nornir_scrapli/connection.py", line 98, in open
    connection = Scrapli(**parameters, platform=final_platform)
  File "/home/lj/NetDevOps/Templating/.venv/lib/python3.10/site-packages/scrapli/factory.py", line 497, in __new__
    final_driver, additional_kwargs = cls._get_driver(platform=platform, variant=variant)
  File "/home/lj/NetDevOps/Templating/.venv/lib/python3.10/site-packages/scrapli/factory.py", line 326, in _get_driver
    final_driver, additional_kwargs = cls._get_community_driver(
  File "/home/lj/NetDevOps/Templating/.venv/lib/python3.10/site-packages/scrapli/factory.py", line 288, in _get_community_driver
    platform_details = _get_community_platform_details(
  File "/home/lj/NetDevOps/Templating/.venv/lib/python3.10/site-packages/scrapli/factory.py", line 168, in _get_community_platform_details
    raise ScrapliModuleNotFound(warning) from exc
scrapli.exceptions.ScrapliModuleNotFound: 

********************************************************************************** Module not found! ***********************************************************************************
       Scrapli Community platform 'iOS` not found!
To resolve this issue, ensure you have the correct platform name, and that a scrapli  community platform of that name exists!        
****************************************************************************************************************************************************************************************


The above exception was the direct cause of the following exception:

Traceback (most recent call last):
  File "/home/lj/NetDevOps/Templating/.venv/lib/python3.10/site-packages/nornir/core/task.py", line 99, in start
    r = self.task(self, **self.params)
  File "/home/lj/NetDevOps/Templating/.venv/lib/python3.10/site-packages/nornir_scrapli/tasks/core/send_command.py", line 36, in send_command
    scrapli_conn = task.host.get_connection("scrapli", task.nornir.config)
  File "/home/lj/NetDevOps/Templating/.venv/lib/python3.10/site-packages/nornir/core/inventory.py", line 494, in get_connection
    self.open_connection(
  File "/home/lj/NetDevOps/Templating/.venv/lib/python3.10/site-packages/nornir/core/inventory.py", line 546, in open_connection
    conn_obj.open(
  File "/home/lj/NetDevOps/Templating/.venv/lib/python3.10/site-packages/nornir_scrapli/connection.py", line 100, in open
    raise NornirScrapliInvalidPlatform(
nornir_scrapli.exceptions.NornirScrapliInvalidPlatform: Provided platform `iOS` is not a valid scrapli or napalm platform, or is not a valid scrapli-community platform.

2022-10-11 18:10:07,906 - nornir.core.task -    ERROR -      start() - Host 'R1': task 'test_show_command' failed with traceback:
Traceback (most recent call last):
  File "/home/lj/NetDevOps/Templating/.venv/lib/python3.10/site-packages/nornir/core/task.py", line 99, in start
    r = self.task(self, **self.params)
  File "/home/lj/NetDevOps/Netbox/runbook2.py", line 12, in test_show_command
    task.run(task=send_command, command="show ip interface brief")
  File "/home/lj/NetDevOps/Templating/.venv/lib/python3.10/site-packages/nornir/core/task.py", line 174, in run
    raise NornirSubTaskError(task=run_task, result=r)
nornir.core.exceptions.NornirSubTaskError: Subtask: send_command (failed)


2022-10-11 18:10:07,906 - nornir.core.task -    ERROR -      start() - Host 'R2': task 'send_command' failed with traceback:
Traceback (most recent call last):
  File "/home/lj/NetDevOps/Templating/.venv/lib/python3.10/site-packages/scrapli/factory.py", line 157, in _get_community_platform_details
    scrapli_community_platform = importlib.import_module(
  File "/usr/lib/python3.10/importlib/__init__.py", line 126, in import_module
    return _bootstrap._gcd_import(name[level:], package, level)
  File "<frozen importlib._bootstrap>", line 1050, in _gcd_import
  File "<frozen importlib._bootstrap>", line 1027, in _find_and_load
  File "<frozen importlib._bootstrap>", line 1004, in _find_and_load_unlocked
ModuleNotFoundError: No module named 'scrapli_community.iOS'

The above exception was the direct cause of the following exception:

Traceback (most recent call last):
  File "/home/lj/NetDevOps/Templating/.venv/lib/python3.10/site-packages/nornir_scrapli/connection.py", line 98, in open
    connection = Scrapli(**parameters, platform=final_platform)
  File "/home/lj/NetDevOps/Templating/.venv/lib/python3.10/site-packages/scrapli/factory.py", line 497, in __new__
    final_driver, additional_kwargs = cls._get_driver(platform=platform, variant=variant)
  File "/home/lj/NetDevOps/Templating/.venv/lib/python3.10/site-packages/scrapli/factory.py", line 326, in _get_driver
    final_driver, additional_kwargs = cls._get_community_driver(
  File "/home/lj/NetDevOps/Templating/.venv/lib/python3.10/site-packages/scrapli/factory.py", line 288, in _get_community_driver
    platform_details = _get_community_platform_details(
  File "/home/lj/NetDevOps/Templating/.venv/lib/python3.10/site-packages/scrapli/factory.py", line 168, in _get_community_platform_details
    raise ScrapliModuleNotFound(warning) from exc
scrapli.exceptions.ScrapliModuleNotFound: 

********************************************************************************** Module not found! ***********************************************************************************
       Scrapli Community platform 'iOS` not found!
To resolve this issue, ensure you have the correct platform name, and that a scrapli  community platform of that name exists!        
****************************************************************************************************************************************************************************************


The above exception was the direct cause of the following exception:

Traceback (most recent call last):
  File "/home/lj/NetDevOps/Templating/.venv/lib/python3.10/site-packages/nornir/core/task.py", line 99, in start
    r = self.task(self, **self.params)
  File "/home/lj/NetDevOps/Templating/.venv/lib/python3.10/site-packages/nornir_scrapli/tasks/core/send_command.py", line 36, in send_command
    scrapli_conn = task.host.get_connection("scrapli", task.nornir.config)
  File "/home/lj/NetDevOps/Templating/.venv/lib/python3.10/site-packages/nornir/core/inventory.py", line 494, in get_connection
    self.open_connection(
  File "/home/lj/NetDevOps/Templating/.venv/lib/python3.10/site-packages/nornir/core/inventory.py", line 546, in open_connection
    conn_obj.open(
  File "/home/lj/NetDevOps/Templating/.venv/lib/python3.10/site-packages/nornir_scrapli/connection.py", line 100, in open
    raise NornirScrapliInvalidPlatform(
nornir_scrapli.exceptions.NornirScrapliInvalidPlatform: Provided platform `iOS` is not a valid scrapli or napalm platform, or is not a valid scrapli-community platform.

2022-10-11 18:10:07,907 - nornir.core.task -    ERROR -      start() - Host 'R2': task 'test_show_command' failed with traceback:
Traceback (most recent call last):
  File "/home/lj/NetDevOps/Templating/.venv/lib/python3.10/site-packages/nornir/core/task.py", line 99, in start
    r = self.task(self, **self.params)
  File "/home/lj/NetDevOps/Netbox/runbook2.py", line 12, in test_show_command
    task.run(task=send_command, command="show ip interface brief")
  File "/home/lj/NetDevOps/Templating/.venv/lib/python3.10/site-packages/nornir/core/task.py", line 174, in run
    raise NornirSubTaskError(task=run_task, result=r)
nornir.core.exceptions.NornirSubTaskError: Subtask: send_command (failed)


2022-10-11 18:10:07,907 - nornir.core.task -    ERROR -      start() - Host 'R3': task 'send_command' failed with traceback:
Traceback (most recent call last):
  File "/home/lj/NetDevOps/Templating/.venv/lib/python3.10/site-packages/scrapli/factory.py", line 157, in _get_community_platform_details
    scrapli_community_platform = importlib.import_module(
  File "/usr/lib/python3.10/importlib/__init__.py", line 126, in import_module
    return _bootstrap._gcd_import(name[level:], package, level)
  File "<frozen importlib._bootstrap>", line 1050, in _gcd_import
  File "<frozen importlib._bootstrap>", line 1027, in _find_and_load
  File "<frozen importlib._bootstrap>", line 1004, in _find_and_load_unlocked
ModuleNotFoundError: No module named 'scrapli_community.iOS'

The above exception was the direct cause of the following exception:

Traceback (most recent call last):
  File "/home/lj/NetDevOps/Templating/.venv/lib/python3.10/site-packages/nornir_scrapli/connection.py", line 98, in open
    connection = Scrapli(**parameters, platform=final_platform)
  File "/home/lj/NetDevOps/Templating/.venv/lib/python3.10/site-packages/scrapli/factory.py", line 497, in __new__
    final_driver, additional_kwargs = cls._get_driver(platform=platform, variant=variant)
  File "/home/lj/NetDevOps/Templating/.venv/lib/python3.10/site-packages/scrapli/factory.py", line 326, in _get_driver
    final_driver, additional_kwargs = cls._get_community_driver(
  File "/home/lj/NetDevOps/Templating/.venv/lib/python3.10/site-packages/scrapli/factory.py", line 288, in _get_community_driver
    platform_details = _get_community_platform_details(
  File "/home/lj/NetDevOps/Templating/.venv/lib/python3.10/site-packages/scrapli/factory.py", line 168, in _get_community_platform_details
    raise ScrapliModuleNotFound(warning) from exc
scrapli.exceptions.ScrapliModuleNotFound: 

********************************************************************************** Module not found! ***********************************************************************************
       Scrapli Community platform 'iOS` not found!
To resolve this issue, ensure you have the correct platform name, and that a scrapli  community platform of that name exists!        
****************************************************************************************************************************************************************************************


The above exception was the direct cause of the following exception:

Traceback (most recent call last):
  File "/home/lj/NetDevOps/Templating/.venv/lib/python3.10/site-packages/nornir/core/task.py", line 99, in start
    r = self.task(self, **self.params)
  File "/home/lj/NetDevOps/Templating/.venv/lib/python3.10/site-packages/nornir_scrapli/tasks/core/send_command.py", line 36, in send_command
    scrapli_conn = task.host.get_connection("scrapli", task.nornir.config)
  File "/home/lj/NetDevOps/Templating/.venv/lib/python3.10/site-packages/nornir/core/inventory.py", line 494, in get_connection
    self.open_connection(
  File "/home/lj/NetDevOps/Templating/.venv/lib/python3.10/site-packages/nornir/core/inventory.py", line 546, in open_connection
    conn_obj.open(
  File "/home/lj/NetDevOps/Templating/.venv/lib/python3.10/site-packages/nornir_scrapli/connection.py", line 100, in open
    raise NornirScrapliInvalidPlatform(
nornir_scrapli.exceptions.NornirScrapliInvalidPlatform: Provided platform `iOS` is not a valid scrapli or napalm platform, or is not a valid scrapli-community platform.

2022-10-11 18:10:07,907 - nornir.core.task -    ERROR -      start() - Host 'R3': task 'test_show_command' failed with traceback:
Traceback (most recent call last):
  File "/home/lj/NetDevOps/Templating/.venv/lib/python3.10/site-packages/nornir/core/task.py", line 99, in start
    r = self.task(self, **self.params)
  File "/home/lj/NetDevOps/Netbox/runbook2.py", line 12, in test_show_command
    task.run(task=send_command, command="show ip interface brief")
  File "/home/lj/NetDevOps/Templating/.venv/lib/python3.10/site-packages/nornir/core/task.py", line 174, in run
    raise NornirSubTaskError(task=run_task, result=r)
nornir.core.exceptions.NornirSubTaskError: Subtask: send_command (failed)


2022-10-11 18:10:07,908 - nornir.core.task -    ERROR -      start() - Host 'R4': task 'send_command' failed with traceback:
Traceback (most recent call last):
  File "/home/lj/NetDevOps/Templating/.venv/lib/python3.10/site-packages/scrapli/factory.py", line 157, in _get_community_platform_details
    scrapli_community_platform = importlib.import_module(
  File "/usr/lib/python3.10/importlib/__init__.py", line 126, in import_module
    return _bootstrap._gcd_import(name[level:], package, level)
  File "<frozen importlib._bootstrap>", line 1050, in _gcd_import
  File "<frozen importlib._bootstrap>", line 1027, in _find_and_load
  File "<frozen importlib._bootstrap>", line 1004, in _find_and_load_unlocked
ModuleNotFoundError: No module named 'scrapli_community.iOS'

The above exception was the direct cause of the following exception:

Traceback (most recent call last):
  File "/home/lj/NetDevOps/Templating/.venv/lib/python3.10/site-packages/nornir_scrapli/connection.py", line 98, in open
    connection = Scrapli(**parameters, platform=final_platform)
  File "/home/lj/NetDevOps/Templating/.venv/lib/python3.10/site-packages/scrapli/factory.py", line 497, in __new__
    final_driver, additional_kwargs = cls._get_driver(platform=platform, variant=variant)
  File "/home/lj/NetDevOps/Templating/.venv/lib/python3.10/site-packages/scrapli/factory.py", line 326, in _get_driver
    final_driver, additional_kwargs = cls._get_community_driver(
  File "/home/lj/NetDevOps/Templating/.venv/lib/python3.10/site-packages/scrapli/factory.py", line 288, in _get_community_driver
    platform_details = _get_community_platform_details(
  File "/home/lj/NetDevOps/Templating/.venv/lib/python3.10/site-packages/scrapli/factory.py", line 168, in _get_community_platform_details
    raise ScrapliModuleNotFound(warning) from exc
scrapli.exceptions.ScrapliModuleNotFound: 

********************************************************************************** Module not found! ***********************************************************************************
       Scrapli Community platform 'iOS` not found!
To resolve this issue, ensure you have the correct platform name, and that a scrapli  community platform of that name exists!        
****************************************************************************************************************************************************************************************


The above exception was the direct cause of the following exception:

Traceback (most recent call last):
  File "/home/lj/NetDevOps/Templating/.venv/lib/python3.10/site-packages/nornir/core/task.py", line 99, in start
    r = self.task(self, **self.params)
  File "/home/lj/NetDevOps/Templating/.venv/lib/python3.10/site-packages/nornir_scrapli/tasks/core/send_command.py", line 36, in send_command
    scrapli_conn = task.host.get_connection("scrapli", task.nornir.config)
  File "/home/lj/NetDevOps/Templating/.venv/lib/python3.10/site-packages/nornir/core/inventory.py", line 494, in get_connection
    self.open_connection(
  File "/home/lj/NetDevOps/Templating/.venv/lib/python3.10/site-packages/nornir/core/inventory.py", line 546, in open_connection
    conn_obj.open(
  File "/home/lj/NetDevOps/Templating/.venv/lib/python3.10/site-packages/nornir_scrapli/connection.py", line 100, in open
    raise NornirScrapliInvalidPlatform(
nornir_scrapli.exceptions.NornirScrapliInvalidPlatform: Provided platform `iOS` is not a valid scrapli or napalm platform, or is not a valid scrapli-community platform.

2022-10-11 18:10:07,908 - nornir.core.task -    ERROR -      start() - Host 'R4': task 'test_show_command' failed with traceback:
Traceback (most recent call last):
  File "/home/lj/NetDevOps/Templating/.venv/lib/python3.10/site-packages/nornir/core/task.py", line 99, in start
    r = self.task(self, **self.params)
  File "/home/lj/NetDevOps/Netbox/runbook2.py", line 12, in test_show_command
    task.run(task=send_command, command="show ip interface brief")
  File "/home/lj/NetDevOps/Templating/.venv/lib/python3.10/site-packages/nornir/core/task.py", line 174, in run
    raise NornirSubTaskError(task=run_task, result=r)
nornir.core.exceptions.NornirSubTaskError: Subtask: send_command (failed)


2022-10-11 18:12:02,610 -  nornir.core -     INFO -        run() - Running task 'randomtest' with args {} on 4 hosts
2022-10-11 18:15:22,529 -  nornir.core -     INFO -        run() - Running task 'test_show_command' with args {} on 4 hosts
2022-10-11 18:15:22,531 - nornir.core.task -    ERROR -      start() - Host 'R1': task 'send_command' failed with traceback:
Traceback (most recent call last):
  File "/home/lj/NetDevOps/Templating/.venv/lib/python3.10/site-packages/scrapli/factory.py", line 157, in _get_community_platform_details
    scrapli_community_platform = importlib.import_module(
  File "/usr/lib/python3.10/importlib/__init__.py", line 126, in import_module
    return _bootstrap._gcd_import(name[level:], package, level)
  File "<frozen importlib._bootstrap>", line 1050, in _gcd_import
  File "<frozen importlib._bootstrap>", line 1027, in _find_and_load
  File "<frozen importlib._bootstrap>", line 1004, in _find_and_load_unlocked
ModuleNotFoundError: No module named 'scrapli_community.iOS'

The above exception was the direct cause of the following exception:

Traceback (most recent call last):
  File "/home/lj/NetDevOps/Templating/.venv/lib/python3.10/site-packages/nornir_scrapli/connection.py", line 98, in open
    connection = Scrapli(**parameters, platform=final_platform)
  File "/home/lj/NetDevOps/Templating/.venv/lib/python3.10/site-packages/scrapli/factory.py", line 497, in __new__
    final_driver, additional_kwargs = cls._get_driver(platform=platform, variant=variant)
  File "/home/lj/NetDevOps/Templating/.venv/lib/python3.10/site-packages/scrapli/factory.py", line 326, in _get_driver
    final_driver, additional_kwargs = cls._get_community_driver(
  File "/home/lj/NetDevOps/Templating/.venv/lib/python3.10/site-packages/scrapli/factory.py", line 288, in _get_community_driver
    platform_details = _get_community_platform_details(
  File "/home/lj/NetDevOps/Templating/.venv/lib/python3.10/site-packages/scrapli/factory.py", line 168, in _get_community_platform_details
    raise ScrapliModuleNotFound(warning) from exc
scrapli.exceptions.ScrapliModuleNotFound: 

********************************************************************************** Module not found! ***********************************************************************************
       Scrapli Community platform 'iOS` not found!
To resolve this issue, ensure you have the correct platform name, and that a scrapli  community platform of that name exists!        
****************************************************************************************************************************************************************************************


The above exception was the direct cause of the following exception:

Traceback (most recent call last):
  File "/home/lj/NetDevOps/Templating/.venv/lib/python3.10/site-packages/nornir/core/task.py", line 99, in start
    r = self.task(self, **self.params)
  File "/home/lj/NetDevOps/Templating/.venv/lib/python3.10/site-packages/nornir_scrapli/tasks/core/send_command.py", line 36, in send_command
    scrapli_conn = task.host.get_connection("scrapli", task.nornir.config)
  File "/home/lj/NetDevOps/Templating/.venv/lib/python3.10/site-packages/nornir/core/inventory.py", line 494, in get_connection
    self.open_connection(
  File "/home/lj/NetDevOps/Templating/.venv/lib/python3.10/site-packages/nornir/core/inventory.py", line 546, in open_connection
    conn_obj.open(
  File "/home/lj/NetDevOps/Templating/.venv/lib/python3.10/site-packages/nornir_scrapli/connection.py", line 100, in open
    raise NornirScrapliInvalidPlatform(
nornir_scrapli.exceptions.NornirScrapliInvalidPlatform: Provided platform `iOS` is not a valid scrapli or napalm platform, or is not a valid scrapli-community platform.

2022-10-11 18:15:22,532 - nornir.core.task -    ERROR -      start() - Host 'R1': task 'test_show_command' failed with traceback:
Traceback (most recent call last):
  File "/home/lj/NetDevOps/Templating/.venv/lib/python3.10/site-packages/nornir/core/task.py", line 99, in start
    r = self.task(self, **self.params)
  File "/home/lj/NetDevOps/Netbox/runbook2.py", line 13, in test_show_command
    task.run(task=send_command, command="show ip interface brief")
  File "/home/lj/NetDevOps/Templating/.venv/lib/python3.10/site-packages/nornir/core/task.py", line 174, in run
    raise NornirSubTaskError(task=run_task, result=r)
nornir.core.exceptions.NornirSubTaskError: Subtask: send_command (failed)


2022-10-11 18:15:22,532 - nornir.core.task -    ERROR -      start() - Host 'R2': task 'send_command' failed with traceback:
Traceback (most recent call last):
  File "/home/lj/NetDevOps/Templating/.venv/lib/python3.10/site-packages/scrapli/factory.py", line 157, in _get_community_platform_details
    scrapli_community_platform = importlib.import_module(
  File "/usr/lib/python3.10/importlib/__init__.py", line 126, in import_module
    return _bootstrap._gcd_import(name[level:], package, level)
  File "<frozen importlib._bootstrap>", line 1050, in _gcd_import
  File "<frozen importlib._bootstrap>", line 1027, in _find_and_load
  File "<frozen importlib._bootstrap>", line 1004, in _find_and_load_unlocked
ModuleNotFoundError: No module named 'scrapli_community.iOS'

The above exception was the direct cause of the following exception:

Traceback (most recent call last):
  File "/home/lj/NetDevOps/Templating/.venv/lib/python3.10/site-packages/nornir_scrapli/connection.py", line 98, in open
    connection = Scrapli(**parameters, platform=final_platform)
  File "/home/lj/NetDevOps/Templating/.venv/lib/python3.10/site-packages/scrapli/factory.py", line 497, in __new__
    final_driver, additional_kwargs = cls._get_driver(platform=platform, variant=variant)
  File "/home/lj/NetDevOps/Templating/.venv/lib/python3.10/site-packages/scrapli/factory.py", line 326, in _get_driver
    final_driver, additional_kwargs = cls._get_community_driver(
  File "/home/lj/NetDevOps/Templating/.venv/lib/python3.10/site-packages/scrapli/factory.py", line 288, in _get_community_driver
    platform_details = _get_community_platform_details(
  File "/home/lj/NetDevOps/Templating/.venv/lib/python3.10/site-packages/scrapli/factory.py", line 168, in _get_community_platform_details
    raise ScrapliModuleNotFound(warning) from exc
scrapli.exceptions.ScrapliModuleNotFound: 

********************************************************************************** Module not found! ***********************************************************************************
       Scrapli Community platform 'iOS` not found!
To resolve this issue, ensure you have the correct platform name, and that a scrapli  community platform of that name exists!        
****************************************************************************************************************************************************************************************


The above exception was the direct cause of the following exception:

Traceback (most recent call last):
  File "/home/lj/NetDevOps/Templating/.venv/lib/python3.10/site-packages/nornir/core/task.py", line 99, in start
    r = self.task(self, **self.params)
  File "/home/lj/NetDevOps/Templating/.venv/lib/python3.10/site-packages/nornir_scrapli/tasks/core/send_command.py", line 36, in send_command
    scrapli_conn = task.host.get_connection("scrapli", task.nornir.config)
  File "/home/lj/NetDevOps/Templating/.venv/lib/python3.10/site-packages/nornir/core/inventory.py", line 494, in get_connection
    self.open_connection(
  File "/home/lj/NetDevOps/Templating/.venv/lib/python3.10/site-packages/nornir/core/inventory.py", line 546, in open_connection
    conn_obj.open(
  File "/home/lj/NetDevOps/Templating/.venv/lib/python3.10/site-packages/nornir_scrapli/connection.py", line 100, in open
    raise NornirScrapliInvalidPlatform(
nornir_scrapli.exceptions.NornirScrapliInvalidPlatform: Provided platform `iOS` is not a valid scrapli or napalm platform, or is not a valid scrapli-community platform.

2022-10-11 18:15:22,532 - nornir.core.task -    ERROR -      start() - Host 'R2': task 'test_show_command' failed with traceback:
Traceback (most recent call last):
  File "/home/lj/NetDevOps/Templating/.venv/lib/python3.10/site-packages/nornir/core/task.py", line 99, in start
    r = self.task(self, **self.params)
  File "/home/lj/NetDevOps/Netbox/runbook2.py", line 13, in test_show_command
    task.run(task=send_command, command="show ip interface brief")
  File "/home/lj/NetDevOps/Templating/.venv/lib/python3.10/site-packages/nornir/core/task.py", line 174, in run
    raise NornirSubTaskError(task=run_task, result=r)
nornir.core.exceptions.NornirSubTaskError: Subtask: send_command (failed)


2022-10-11 18:15:22,533 - nornir.core.task -    ERROR -      start() - Host 'R3': task 'send_command' failed with traceback:
Traceback (most recent call last):
  File "/home/lj/NetDevOps/Templating/.venv/lib/python3.10/site-packages/scrapli/factory.py", line 157, in _get_community_platform_details
    scrapli_community_platform = importlib.import_module(
  File "/usr/lib/python3.10/importlib/__init__.py", line 126, in import_module
    return _bootstrap._gcd_import(name[level:], package, level)
  File "<frozen importlib._bootstrap>", line 1050, in _gcd_import
  File "<frozen importlib._bootstrap>", line 1027, in _find_and_load
  File "<frozen importlib._bootstrap>", line 1004, in _find_and_load_unlocked
ModuleNotFoundError: No module named 'scrapli_community.iOS'

The above exception was the direct cause of the following exception:

Traceback (most recent call last):
  File "/home/lj/NetDevOps/Templating/.venv/lib/python3.10/site-packages/nornir_scrapli/connection.py", line 98, in open
    connection = Scrapli(**parameters, platform=final_platform)
  File "/home/lj/NetDevOps/Templating/.venv/lib/python3.10/site-packages/scrapli/factory.py", line 497, in __new__
    final_driver, additional_kwargs = cls._get_driver(platform=platform, variant=variant)
  File "/home/lj/NetDevOps/Templating/.venv/lib/python3.10/site-packages/scrapli/factory.py", line 326, in _get_driver
    final_driver, additional_kwargs = cls._get_community_driver(
  File "/home/lj/NetDevOps/Templating/.venv/lib/python3.10/site-packages/scrapli/factory.py", line 288, in _get_community_driver
    platform_details = _get_community_platform_details(
  File "/home/lj/NetDevOps/Templating/.venv/lib/python3.10/site-packages/scrapli/factory.py", line 168, in _get_community_platform_details
    raise ScrapliModuleNotFound(warning) from exc
scrapli.exceptions.ScrapliModuleNotFound: 

********************************************************************************** Module not found! ***********************************************************************************
       Scrapli Community platform 'iOS` not found!
To resolve this issue, ensure you have the correct platform name, and that a scrapli  community platform of that name exists!        
****************************************************************************************************************************************************************************************


The above exception was the direct cause of the following exception:

Traceback (most recent call last):
  File "/home/lj/NetDevOps/Templating/.venv/lib/python3.10/site-packages/nornir/core/task.py", line 99, in start
    r = self.task(self, **self.params)
  File "/home/lj/NetDevOps/Templating/.venv/lib/python3.10/site-packages/nornir_scrapli/tasks/core/send_command.py", line 36, in send_command
    scrapli_conn = task.host.get_connection("scrapli", task.nornir.config)
  File "/home/lj/NetDevOps/Templating/.venv/lib/python3.10/site-packages/nornir/core/inventory.py", line 494, in get_connection
    self.open_connection(
  File "/home/lj/NetDevOps/Templating/.venv/lib/python3.10/site-packages/nornir/core/inventory.py", line 546, in open_connection
    conn_obj.open(
  File "/home/lj/NetDevOps/Templating/.venv/lib/python3.10/site-packages/nornir_scrapli/connection.py", line 100, in open
    raise NornirScrapliInvalidPlatform(
nornir_scrapli.exceptions.NornirScrapliInvalidPlatform: Provided platform `iOS` is not a valid scrapli or napalm platform, or is not a valid scrapli-community platform.

2022-10-11 18:15:22,533 - nornir.core.task -    ERROR -      start() - Host 'R3': task 'test_show_command' failed with traceback:
Traceback (most recent call last):
  File "/home/lj/NetDevOps/Templating/.venv/lib/python3.10/site-packages/nornir/core/task.py", line 99, in start
    r = self.task(self, **self.params)
  File "/home/lj/NetDevOps/Netbox/runbook2.py", line 13, in test_show_command
    task.run(task=send_command, command="show ip interface brief")
  File "/home/lj/NetDevOps/Templating/.venv/lib/python3.10/site-packages/nornir/core/task.py", line 174, in run
    raise NornirSubTaskError(task=run_task, result=r)
nornir.core.exceptions.NornirSubTaskError: Subtask: send_command (failed)


2022-10-11 18:15:22,534 - nornir.core.task -    ERROR -      start() - Host 'R4': task 'send_command' failed with traceback:
Traceback (most recent call last):
  File "/home/lj/NetDevOps/Templating/.venv/lib/python3.10/site-packages/scrapli/factory.py", line 157, in _get_community_platform_details
    scrapli_community_platform = importlib.import_module(
  File "/usr/lib/python3.10/importlib/__init__.py", line 126, in import_module
    return _bootstrap._gcd_import(name[level:], package, level)
  File "<frozen importlib._bootstrap>", line 1050, in _gcd_import
  File "<frozen importlib._bootstrap>", line 1027, in _find_and_load
  File "<frozen importlib._bootstrap>", line 1004, in _find_and_load_unlocked
ModuleNotFoundError: No module named 'scrapli_community.iOS'

The above exception was the direct cause of the following exception:

Traceback (most recent call last):
  File "/home/lj/NetDevOps/Templating/.venv/lib/python3.10/site-packages/nornir_scrapli/connection.py", line 98, in open
    connection = Scrapli(**parameters, platform=final_platform)
  File "/home/lj/NetDevOps/Templating/.venv/lib/python3.10/site-packages/scrapli/factory.py", line 497, in __new__
    final_driver, additional_kwargs = cls._get_driver(platform=platform, variant=variant)
  File "/home/lj/NetDevOps/Templating/.venv/lib/python3.10/site-packages/scrapli/factory.py", line 326, in _get_driver
    final_driver, additional_kwargs = cls._get_community_driver(
  File "/home/lj/NetDevOps/Templating/.venv/lib/python3.10/site-packages/scrapli/factory.py", line 288, in _get_community_driver
    platform_details = _get_community_platform_details(
  File "/home/lj/NetDevOps/Templating/.venv/lib/python3.10/site-packages/scrapli/factory.py", line 168, in _get_community_platform_details
    raise ScrapliModuleNotFound(warning) from exc
scrapli.exceptions.ScrapliModuleNotFound: 

********************************************************************************** Module not found! ***********************************************************************************
       Scrapli Community platform 'iOS` not found!
To resolve this issue, ensure you have the correct platform name, and that a scrapli  community platform of that name exists!        
****************************************************************************************************************************************************************************************


The above exception was the direct cause of the following exception:

Traceback (most recent call last):
  File "/home/lj/NetDevOps/Templating/.venv/lib/python3.10/site-packages/nornir/core/task.py", line 99, in start
    r = self.task(self, **self.params)
  File "/home/lj/NetDevOps/Templating/.venv/lib/python3.10/site-packages/nornir_scrapli/tasks/core/send_command.py", line 36, in send_command
    scrapli_conn = task.host.get_connection("scrapli", task.nornir.config)
  File "/home/lj/NetDevOps/Templating/.venv/lib/python3.10/site-packages/nornir/core/inventory.py", line 494, in get_connection
    self.open_connection(
  File "/home/lj/NetDevOps/Templating/.venv/lib/python3.10/site-packages/nornir/core/inventory.py", line 546, in open_connection
    conn_obj.open(
  File "/home/lj/NetDevOps/Templating/.venv/lib/python3.10/site-packages/nornir_scrapli/connection.py", line 100, in open
    raise NornirScrapliInvalidPlatform(
nornir_scrapli.exceptions.NornirScrapliInvalidPlatform: Provided platform `iOS` is not a valid scrapli or napalm platform, or is not a valid scrapli-community platform.

2022-10-11 18:15:22,534 - nornir.core.task -    ERROR -      start() - Host 'R4': task 'test_show_command' failed with traceback:
Traceback (most recent call last):
  File "/home/lj/NetDevOps/Templating/.venv/lib/python3.10/site-packages/nornir/core/task.py", line 99, in start
    r = self.task(self, **self.params)
  File "/home/lj/NetDevOps/Netbox/runbook2.py", line 13, in test_show_command
    task.run(task=send_command, command="show ip interface brief")
  File "/home/lj/NetDevOps/Templating/.venv/lib/python3.10/site-packages/nornir/core/task.py", line 174, in run
    raise NornirSubTaskError(task=run_task, result=r)
nornir.core.exceptions.NornirSubTaskError: Subtask: send_command (failed)


2022-10-11 18:20:02,160 -  nornir.core -     INFO -        run() - Running task 'test_show_command' with args {} on 4 hosts
2022-10-11 18:20:02,223 - nornir.core.task -    ERROR -      start() - Host 'R1': task 'send_command' failed with traceback:
Traceback (most recent call last):
  File "/home/lj/NetDevOps/Templating/.venv/lib/python3.10/site-packages/nornir/core/task.py", line 99, in start
    r = self.task(self, **self.params)
  File "/home/lj/NetDevOps/Templating/.venv/lib/python3.10/site-packages/nornir_scrapli/tasks/core/send_command.py", line 36, in send_command
    scrapli_conn = task.host.get_connection("scrapli", task.nornir.config)
  File "/home/lj/NetDevOps/Templating/.venv/lib/python3.10/site-packages/nornir/core/inventory.py", line 494, in get_connection
    self.open_connection(
  File "/home/lj/NetDevOps/Templating/.venv/lib/python3.10/site-packages/nornir/core/inventory.py", line 546, in open_connection
    conn_obj.open(
  File "/home/lj/NetDevOps/Templating/.venv/lib/python3.10/site-packages/nornir_scrapli/connection.py", line 105, in open
    connection.open()
  File "/home/lj/NetDevOps/Templating/.venv/lib/python3.10/site-packages/scrapli/driver/base/sync_driver.py", line 88, in open
    self.channel.channel_authenticate_ssh(
  File "/home/lj/NetDevOps/Templating/.venv/lib/python3.10/site-packages/scrapli/decorators.py", line 216, in decorate
    return _multiprocessing_timeout(
  File "/home/lj/NetDevOps/Templating/.venv/lib/python3.10/site-packages/scrapli/decorators.py", line 113, in _multiprocessing_timeout
    return future.result()
  File "/usr/lib/python3.10/concurrent/futures/_base.py", line 451, in result
    return self.__get_result()
  File "/usr/lib/python3.10/concurrent/futures/_base.py", line 403, in __get_result
    raise self._exception
  File "/usr/lib/python3.10/concurrent/futures/thread.py", line 58, in run
    result = self.fn(*self.args, **self.kwargs)
  File "/home/lj/NetDevOps/Templating/.venv/lib/python3.10/site-packages/scrapli/channel/sync_channel.py", line 290, in channel_authenticate_ssh
    self._ssh_message_handler(output=authenticate_buf)
  File "/home/lj/NetDevOps/Templating/.venv/lib/python3.10/site-packages/scrapli/channel/base_channel.py", line 432, in _ssh_message_handler
    raise ScrapliAuthenticationFailed(msg)
scrapli.exceptions.ScrapliAuthenticationFailed: Host key verification failed

2022-10-11 18:20:02,224 - nornir.core.task -    ERROR -      start() - Host 'R1': task 'test_show_command' failed with traceback:
Traceback (most recent call last):
  File "/home/lj/NetDevOps/Templating/.venv/lib/python3.10/site-packages/nornir/core/task.py", line 99, in start
    r = self.task(self, **self.params)
  File "/home/lj/NetDevOps/Netbox/runbook2.py", line 13, in test_show_command
    task.run(task=send_command, command="show ip interface brief")
  File "/home/lj/NetDevOps/Templating/.venv/lib/python3.10/site-packages/nornir/core/task.py", line 174, in run
    raise NornirSubTaskError(task=run_task, result=r)
nornir.core.exceptions.NornirSubTaskError: Subtask: send_command (failed)


2022-10-11 18:20:02,278 - nornir.core.task -    ERROR -      start() - Host 'R2': task 'send_command' failed with traceback:
Traceback (most recent call last):
  File "/home/lj/NetDevOps/Templating/.venv/lib/python3.10/site-packages/nornir/core/task.py", line 99, in start
    r = self.task(self, **self.params)
  File "/home/lj/NetDevOps/Templating/.venv/lib/python3.10/site-packages/nornir_scrapli/tasks/core/send_command.py", line 36, in send_command
    scrapli_conn = task.host.get_connection("scrapli", task.nornir.config)
  File "/home/lj/NetDevOps/Templating/.venv/lib/python3.10/site-packages/nornir/core/inventory.py", line 494, in get_connection
    self.open_connection(
  File "/home/lj/NetDevOps/Templating/.venv/lib/python3.10/site-packages/nornir/core/inventory.py", line 546, in open_connection
    conn_obj.open(
  File "/home/lj/NetDevOps/Templating/.venv/lib/python3.10/site-packages/nornir_scrapli/connection.py", line 105, in open
    connection.open()
  File "/home/lj/NetDevOps/Templating/.venv/lib/python3.10/site-packages/scrapli/driver/base/sync_driver.py", line 88, in open
    self.channel.channel_authenticate_ssh(
  File "/home/lj/NetDevOps/Templating/.venv/lib/python3.10/site-packages/scrapli/decorators.py", line 216, in decorate
    return _multiprocessing_timeout(
  File "/home/lj/NetDevOps/Templating/.venv/lib/python3.10/site-packages/scrapli/decorators.py", line 113, in _multiprocessing_timeout
    return future.result()
  File "/usr/lib/python3.10/concurrent/futures/_base.py", line 451, in result
    return self.__get_result()
  File "/usr/lib/python3.10/concurrent/futures/_base.py", line 403, in __get_result
    raise self._exception
  File "/usr/lib/python3.10/concurrent/futures/thread.py", line 58, in run
    result = self.fn(*self.args, **self.kwargs)
  File "/home/lj/NetDevOps/Templating/.venv/lib/python3.10/site-packages/scrapli/channel/sync_channel.py", line 290, in channel_authenticate_ssh
    self._ssh_message_handler(output=authenticate_buf)
  File "/home/lj/NetDevOps/Templating/.venv/lib/python3.10/site-packages/scrapli/channel/base_channel.py", line 432, in _ssh_message_handler
    raise ScrapliAuthenticationFailed(msg)
scrapli.exceptions.ScrapliAuthenticationFailed: Host key verification failed

2022-10-11 18:20:02,278 - nornir.core.task -    ERROR -      start() - Host 'R2': task 'test_show_command' failed with traceback:
Traceback (most recent call last):
  File "/home/lj/NetDevOps/Templating/.venv/lib/python3.10/site-packages/nornir/core/task.py", line 99, in start
    r = self.task(self, **self.params)
  File "/home/lj/NetDevOps/Netbox/runbook2.py", line 13, in test_show_command
    task.run(task=send_command, command="show ip interface brief")
  File "/home/lj/NetDevOps/Templating/.venv/lib/python3.10/site-packages/nornir/core/task.py", line 174, in run
    raise NornirSubTaskError(task=run_task, result=r)
nornir.core.exceptions.NornirSubTaskError: Subtask: send_command (failed)


2022-10-11 18:20:02,331 - nornir.core.task -    ERROR -      start() - Host 'R3': task 'send_command' failed with traceback:
Traceback (most recent call last):
  File "/home/lj/NetDevOps/Templating/.venv/lib/python3.10/site-packages/nornir/core/task.py", line 99, in start
    r = self.task(self, **self.params)
  File "/home/lj/NetDevOps/Templating/.venv/lib/python3.10/site-packages/nornir_scrapli/tasks/core/send_command.py", line 36, in send_command
    scrapli_conn = task.host.get_connection("scrapli", task.nornir.config)
  File "/home/lj/NetDevOps/Templating/.venv/lib/python3.10/site-packages/nornir/core/inventory.py", line 494, in get_connection
    self.open_connection(
  File "/home/lj/NetDevOps/Templating/.venv/lib/python3.10/site-packages/nornir/core/inventory.py", line 546, in open_connection
    conn_obj.open(
  File "/home/lj/NetDevOps/Templating/.venv/lib/python3.10/site-packages/nornir_scrapli/connection.py", line 105, in open
    connection.open()
  File "/home/lj/NetDevOps/Templating/.venv/lib/python3.10/site-packages/scrapli/driver/base/sync_driver.py", line 88, in open
    self.channel.channel_authenticate_ssh(
  File "/home/lj/NetDevOps/Templating/.venv/lib/python3.10/site-packages/scrapli/decorators.py", line 216, in decorate
    return _multiprocessing_timeout(
  File "/home/lj/NetDevOps/Templating/.venv/lib/python3.10/site-packages/scrapli/decorators.py", line 113, in _multiprocessing_timeout
    return future.result()
  File "/usr/lib/python3.10/concurrent/futures/_base.py", line 451, in result
    return self.__get_result()
  File "/usr/lib/python3.10/concurrent/futures/_base.py", line 403, in __get_result
    raise self._exception
  File "/usr/lib/python3.10/concurrent/futures/thread.py", line 58, in run
    result = self.fn(*self.args, **self.kwargs)
  File "/home/lj/NetDevOps/Templating/.venv/lib/python3.10/site-packages/scrapli/channel/sync_channel.py", line 290, in channel_authenticate_ssh
    self._ssh_message_handler(output=authenticate_buf)
  File "/home/lj/NetDevOps/Templating/.venv/lib/python3.10/site-packages/scrapli/channel/base_channel.py", line 432, in _ssh_message_handler
    raise ScrapliAuthenticationFailed(msg)
scrapli.exceptions.ScrapliAuthenticationFailed: Host key verification failed

2022-10-11 18:20:02,331 - nornir.core.task -    ERROR -      start() - Host 'R3': task 'test_show_command' failed with traceback:
Traceback (most recent call last):
  File "/home/lj/NetDevOps/Templating/.venv/lib/python3.10/site-packages/nornir/core/task.py", line 99, in start
    r = self.task(self, **self.params)
  File "/home/lj/NetDevOps/Netbox/runbook2.py", line 13, in test_show_command
    task.run(task=send_command, command="show ip interface brief")
  File "/home/lj/NetDevOps/Templating/.venv/lib/python3.10/site-packages/nornir/core/task.py", line 174, in run
    raise NornirSubTaskError(task=run_task, result=r)
nornir.core.exceptions.NornirSubTaskError: Subtask: send_command (failed)


2022-10-11 18:20:02,382 - nornir.core.task -    ERROR -      start() - Host 'R4': task 'send_command' failed with traceback:
Traceback (most recent call last):
  File "/home/lj/NetDevOps/Templating/.venv/lib/python3.10/site-packages/nornir/core/task.py", line 99, in start
    r = self.task(self, **self.params)
  File "/home/lj/NetDevOps/Templating/.venv/lib/python3.10/site-packages/nornir_scrapli/tasks/core/send_command.py", line 36, in send_command
    scrapli_conn = task.host.get_connection("scrapli", task.nornir.config)
  File "/home/lj/NetDevOps/Templating/.venv/lib/python3.10/site-packages/nornir/core/inventory.py", line 494, in get_connection
    self.open_connection(
  File "/home/lj/NetDevOps/Templating/.venv/lib/python3.10/site-packages/nornir/core/inventory.py", line 546, in open_connection
    conn_obj.open(
  File "/home/lj/NetDevOps/Templating/.venv/lib/python3.10/site-packages/nornir_scrapli/connection.py", line 105, in open
    connection.open()
  File "/home/lj/NetDevOps/Templating/.venv/lib/python3.10/site-packages/scrapli/driver/base/sync_driver.py", line 88, in open
    self.channel.channel_authenticate_ssh(
  File "/home/lj/NetDevOps/Templating/.venv/lib/python3.10/site-packages/scrapli/decorators.py", line 216, in decorate
    return _multiprocessing_timeout(
  File "/home/lj/NetDevOps/Templating/.venv/lib/python3.10/site-packages/scrapli/decorators.py", line 113, in _multiprocessing_timeout
    return future.result()
  File "/usr/lib/python3.10/concurrent/futures/_base.py", line 451, in result
    return self.__get_result()
  File "/usr/lib/python3.10/concurrent/futures/_base.py", line 403, in __get_result
    raise self._exception
  File "/usr/lib/python3.10/concurrent/futures/thread.py", line 58, in run
    result = self.fn(*self.args, **self.kwargs)
  File "/home/lj/NetDevOps/Templating/.venv/lib/python3.10/site-packages/scrapli/channel/sync_channel.py", line 290, in channel_authenticate_ssh
    self._ssh_message_handler(output=authenticate_buf)
  File "/home/lj/NetDevOps/Templating/.venv/lib/python3.10/site-packages/scrapli/channel/base_channel.py", line 432, in _ssh_message_handler
    raise ScrapliAuthenticationFailed(msg)
scrapli.exceptions.ScrapliAuthenticationFailed: Host key verification failed

2022-10-11 18:20:02,382 - nornir.core.task -    ERROR -      start() - Host 'R4': task 'test_show_command' failed with traceback:
Traceback (most recent call last):
  File "/home/lj/NetDevOps/Templating/.venv/lib/python3.10/site-packages/nornir/core/task.py", line 99, in start
    r = self.task(self, **self.params)
  File "/home/lj/NetDevOps/Netbox/runbook2.py", line 13, in test_show_command
    task.run(task=send_command, command="show ip interface brief")
  File "/home/lj/NetDevOps/Templating/.venv/lib/python3.10/site-packages/nornir/core/task.py", line 174, in run
    raise NornirSubTaskError(task=run_task, result=r)
nornir.core.exceptions.NornirSubTaskError: Subtask: send_command (failed)


2022-10-11 18:26:48,304 -  nornir.core -     INFO -        run() - Running task 'test_show_command' with args {} on 4 hosts
2022-10-11 18:26:48,366 - nornir.core.task -    ERROR -      start() - Host 'R1': task 'send_command' failed with traceback:
Traceback (most recent call last):
  File "/home/lj/NetDevOps/Templating/.venv/lib/python3.10/site-packages/nornir/core/task.py", line 99, in start
    r = self.task(self, **self.params)
  File "/home/lj/NetDevOps/Templating/.venv/lib/python3.10/site-packages/nornir_scrapli/tasks/core/send_command.py", line 36, in send_command
    scrapli_conn = task.host.get_connection("scrapli", task.nornir.config)
  File "/home/lj/NetDevOps/Templating/.venv/lib/python3.10/site-packages/nornir/core/inventory.py", line 494, in get_connection
    self.open_connection(
  File "/home/lj/NetDevOps/Templating/.venv/lib/python3.10/site-packages/nornir/core/inventory.py", line 546, in open_connection
    conn_obj.open(
  File "/home/lj/NetDevOps/Templating/.venv/lib/python3.10/site-packages/nornir_scrapli/connection.py", line 105, in open
    connection.open()
  File "/home/lj/NetDevOps/Templating/.venv/lib/python3.10/site-packages/scrapli/driver/base/sync_driver.py", line 88, in open
    self.channel.channel_authenticate_ssh(
  File "/home/lj/NetDevOps/Templating/.venv/lib/python3.10/site-packages/scrapli/decorators.py", line 216, in decorate
    return _multiprocessing_timeout(
  File "/home/lj/NetDevOps/Templating/.venv/lib/python3.10/site-packages/scrapli/decorators.py", line 113, in _multiprocessing_timeout
    return future.result()
  File "/usr/lib/python3.10/concurrent/futures/_base.py", line 451, in result
    return self.__get_result()
  File "/usr/lib/python3.10/concurrent/futures/_base.py", line 403, in __get_result
    raise self._exception
  File "/usr/lib/python3.10/concurrent/futures/thread.py", line 58, in run
    result = self.fn(*self.args, **self.kwargs)
  File "/home/lj/NetDevOps/Templating/.venv/lib/python3.10/site-packages/scrapli/channel/sync_channel.py", line 290, in channel_authenticate_ssh
    self._ssh_message_handler(output=authenticate_buf)
  File "/home/lj/NetDevOps/Templating/.venv/lib/python3.10/site-packages/scrapli/channel/base_channel.py", line 432, in _ssh_message_handler
    raise ScrapliAuthenticationFailed(msg)
scrapli.exceptions.ScrapliAuthenticationFailed: Host key verification failed

2022-10-11 18:26:48,367 - nornir.core.task -    ERROR -      start() - Host 'R1': task 'test_show_command' failed with traceback:
Traceback (most recent call last):
  File "/home/lj/NetDevOps/Templating/.venv/lib/python3.10/site-packages/nornir/core/task.py", line 99, in start
    r = self.task(self, **self.params)
  File "/home/lj/NetDevOps/Netbox/runbook2.py", line 13, in test_show_command
    task.run(task=send_command, command="show ip interface brief")
  File "/home/lj/NetDevOps/Templating/.venv/lib/python3.10/site-packages/nornir/core/task.py", line 174, in run
    raise NornirSubTaskError(task=run_task, result=r)
nornir.core.exceptions.NornirSubTaskError: Subtask: send_command (failed)


2022-10-11 18:26:48,420 - nornir.core.task -    ERROR -      start() - Host 'R2': task 'send_command' failed with traceback:
Traceback (most recent call last):
  File "/home/lj/NetDevOps/Templating/.venv/lib/python3.10/site-packages/nornir/core/task.py", line 99, in start
    r = self.task(self, **self.params)
  File "/home/lj/NetDevOps/Templating/.venv/lib/python3.10/site-packages/nornir_scrapli/tasks/core/send_command.py", line 36, in send_command
    scrapli_conn = task.host.get_connection("scrapli", task.nornir.config)
  File "/home/lj/NetDevOps/Templating/.venv/lib/python3.10/site-packages/nornir/core/inventory.py", line 494, in get_connection
    self.open_connection(
  File "/home/lj/NetDevOps/Templating/.venv/lib/python3.10/site-packages/nornir/core/inventory.py", line 546, in open_connection
    conn_obj.open(
  File "/home/lj/NetDevOps/Templating/.venv/lib/python3.10/site-packages/nornir_scrapli/connection.py", line 105, in open
    connection.open()
  File "/home/lj/NetDevOps/Templating/.venv/lib/python3.10/site-packages/scrapli/driver/base/sync_driver.py", line 88, in open
    self.channel.channel_authenticate_ssh(
  File "/home/lj/NetDevOps/Templating/.venv/lib/python3.10/site-packages/scrapli/decorators.py", line 216, in decorate
    return _multiprocessing_timeout(
  File "/home/lj/NetDevOps/Templating/.venv/lib/python3.10/site-packages/scrapli/decorators.py", line 113, in _multiprocessing_timeout
    return future.result()
  File "/usr/lib/python3.10/concurrent/futures/_base.py", line 451, in result
    return self.__get_result()
  File "/usr/lib/python3.10/concurrent/futures/_base.py", line 403, in __get_result
    raise self._exception
  File "/usr/lib/python3.10/concurrent/futures/thread.py", line 58, in run
    result = self.fn(*self.args, **self.kwargs)
  File "/home/lj/NetDevOps/Templating/.venv/lib/python3.10/site-packages/scrapli/channel/sync_channel.py", line 290, in channel_authenticate_ssh
    self._ssh_message_handler(output=authenticate_buf)
  File "/home/lj/NetDevOps/Templating/.venv/lib/python3.10/site-packages/scrapli/channel/base_channel.py", line 432, in _ssh_message_handler
    raise ScrapliAuthenticationFailed(msg)
scrapli.exceptions.ScrapliAuthenticationFailed: Host key verification failed

2022-10-11 18:26:48,421 - nornir.core.task -    ERROR -      start() - Host 'R2': task 'test_show_command' failed with traceback:
Traceback (most recent call last):
  File "/home/lj/NetDevOps/Templating/.venv/lib/python3.10/site-packages/nornir/core/task.py", line 99, in start
    r = self.task(self, **self.params)
  File "/home/lj/NetDevOps/Netbox/runbook2.py", line 13, in test_show_command
    task.run(task=send_command, command="show ip interface brief")
  File "/home/lj/NetDevOps/Templating/.venv/lib/python3.10/site-packages/nornir/core/task.py", line 174, in run
    raise NornirSubTaskError(task=run_task, result=r)
nornir.core.exceptions.NornirSubTaskError: Subtask: send_command (failed)


2022-10-11 18:26:48,473 - nornir.core.task -    ERROR -      start() - Host 'R3': task 'send_command' failed with traceback:
Traceback (most recent call last):
  File "/home/lj/NetDevOps/Templating/.venv/lib/python3.10/site-packages/nornir/core/task.py", line 99, in start
    r = self.task(self, **self.params)
  File "/home/lj/NetDevOps/Templating/.venv/lib/python3.10/site-packages/nornir_scrapli/tasks/core/send_command.py", line 36, in send_command
    scrapli_conn = task.host.get_connection("scrapli", task.nornir.config)
  File "/home/lj/NetDevOps/Templating/.venv/lib/python3.10/site-packages/nornir/core/inventory.py", line 494, in get_connection
    self.open_connection(
  File "/home/lj/NetDevOps/Templating/.venv/lib/python3.10/site-packages/nornir/core/inventory.py", line 546, in open_connection
    conn_obj.open(
  File "/home/lj/NetDevOps/Templating/.venv/lib/python3.10/site-packages/nornir_scrapli/connection.py", line 105, in open
    connection.open()
  File "/home/lj/NetDevOps/Templating/.venv/lib/python3.10/site-packages/scrapli/driver/base/sync_driver.py", line 88, in open
    self.channel.channel_authenticate_ssh(
  File "/home/lj/NetDevOps/Templating/.venv/lib/python3.10/site-packages/scrapli/decorators.py", line 216, in decorate
    return _multiprocessing_timeout(
  File "/home/lj/NetDevOps/Templating/.venv/lib/python3.10/site-packages/scrapli/decorators.py", line 113, in _multiprocessing_timeout
    return future.result()
  File "/usr/lib/python3.10/concurrent/futures/_base.py", line 451, in result
    return self.__get_result()
  File "/usr/lib/python3.10/concurrent/futures/_base.py", line 403, in __get_result
    raise self._exception
  File "/usr/lib/python3.10/concurrent/futures/thread.py", line 58, in run
    result = self.fn(*self.args, **self.kwargs)
  File "/home/lj/NetDevOps/Templating/.venv/lib/python3.10/site-packages/scrapli/channel/sync_channel.py", line 290, in channel_authenticate_ssh
    self._ssh_message_handler(output=authenticate_buf)
  File "/home/lj/NetDevOps/Templating/.venv/lib/python3.10/site-packages/scrapli/channel/base_channel.py", line 432, in _ssh_message_handler
    raise ScrapliAuthenticationFailed(msg)
scrapli.exceptions.ScrapliAuthenticationFailed: Host key verification failed

2022-10-11 18:26:48,474 - nornir.core.task -    ERROR -      start() - Host 'R3': task 'test_show_command' failed with traceback:
Traceback (most recent call last):
  File "/home/lj/NetDevOps/Templating/.venv/lib/python3.10/site-packages/nornir/core/task.py", line 99, in start
    r = self.task(self, **self.params)
  File "/home/lj/NetDevOps/Netbox/runbook2.py", line 13, in test_show_command
    task.run(task=send_command, command="show ip interface brief")
  File "/home/lj/NetDevOps/Templating/.venv/lib/python3.10/site-packages/nornir/core/task.py", line 174, in run
    raise NornirSubTaskError(task=run_task, result=r)
nornir.core.exceptions.NornirSubTaskError: Subtask: send_command (failed)


2022-10-11 18:26:48,541 - nornir.core.task -    ERROR -      start() - Host 'R4': task 'send_command' failed with traceback:
Traceback (most recent call last):
  File "/home/lj/NetDevOps/Templating/.venv/lib/python3.10/site-packages/nornir/core/task.py", line 99, in start
    r = self.task(self, **self.params)
  File "/home/lj/NetDevOps/Templating/.venv/lib/python3.10/site-packages/nornir_scrapli/tasks/core/send_command.py", line 36, in send_command
    scrapli_conn = task.host.get_connection("scrapli", task.nornir.config)
  File "/home/lj/NetDevOps/Templating/.venv/lib/python3.10/site-packages/nornir/core/inventory.py", line 494, in get_connection
    self.open_connection(
  File "/home/lj/NetDevOps/Templating/.venv/lib/python3.10/site-packages/nornir/core/inventory.py", line 546, in open_connection
    conn_obj.open(
  File "/home/lj/NetDevOps/Templating/.venv/lib/python3.10/site-packages/nornir_scrapli/connection.py", line 105, in open
    connection.open()
  File "/home/lj/NetDevOps/Templating/.venv/lib/python3.10/site-packages/scrapli/driver/base/sync_driver.py", line 88, in open
    self.channel.channel_authenticate_ssh(
  File "/home/lj/NetDevOps/Templating/.venv/lib/python3.10/site-packages/scrapli/decorators.py", line 216, in decorate
    return _multiprocessing_timeout(
  File "/home/lj/NetDevOps/Templating/.venv/lib/python3.10/site-packages/scrapli/decorators.py", line 113, in _multiprocessing_timeout
    return future.result()
  File "/usr/lib/python3.10/concurrent/futures/_base.py", line 451, in result
    return self.__get_result()
  File "/usr/lib/python3.10/concurrent/futures/_base.py", line 403, in __get_result
    raise self._exception
  File "/usr/lib/python3.10/concurrent/futures/thread.py", line 58, in run
    result = self.fn(*self.args, **self.kwargs)
  File "/home/lj/NetDevOps/Templating/.venv/lib/python3.10/site-packages/scrapli/channel/sync_channel.py", line 290, in channel_authenticate_ssh
    self._ssh_message_handler(output=authenticate_buf)
  File "/home/lj/NetDevOps/Templating/.venv/lib/python3.10/site-packages/scrapli/channel/base_channel.py", line 432, in _ssh_message_handler
    raise ScrapliAuthenticationFailed(msg)
scrapli.exceptions.ScrapliAuthenticationFailed: Host key verification failed

2022-10-11 18:26:48,541 - nornir.core.task -    ERROR -      start() - Host 'R4': task 'test_show_command' failed with traceback:
Traceback (most recent call last):
  File "/home/lj/NetDevOps/Templating/.venv/lib/python3.10/site-packages/nornir/core/task.py", line 99, in start
    r = self.task(self, **self.params)
  File "/home/lj/NetDevOps/Netbox/runbook2.py", line 13, in test_show_command
    task.run(task=send_command, command="show ip interface brief")
  File "/home/lj/NetDevOps/Templating/.venv/lib/python3.10/site-packages/nornir/core/task.py", line 174, in run
    raise NornirSubTaskError(task=run_task, result=r)
nornir.core.exceptions.NornirSubTaskError: Subtask: send_command (failed)


